Workbook
Name acc_tbl: README!$A$20:$A$38
Name acct: Posts!$B$3:$B$6208
Name ai_full: Posts!$V$3:$V$6208
Name ai_st: Posts!$F$3:$F$6208
Name is_ai: Posts!$R$3:$R$6208
Name is_conv: Posts!$S$3:$S$6208
Name n_top: Posts!$T$3:$T$6208
Name T_CRI: Posts!$K$3:$K$6208
Name T_CULT: Posts!$O$3:$O$6208
Name T_DEF: Posts!$P$3:$P$6208
Name T_ECON: Posts!$M$3:$M$6208
Name T_IMM: Posts!$I$3:$I$6208
Name T_ISL: Posts!$J$3:$J$6208
Name T_LAND: Posts!$N$3:$N$6208
Name T_SOV: Posts!$L$3:$L$6208
Name topical: Posts!$U$3:$U$6208

Sheet README
A1: Thesis data workbook
A2: Sheets
A3: README – index, definitions, account table, topic labels
A4: Posts – one row per post (6,206)
A5: Register_AI / Register_Conv – visual register items (287 AI, 486 conventional)
A6: Adoption – AI adoption by account and country
A7: CHES – CHES 2024 placements vs AI adoption
A8: Themes – topic shares
A9: Register – visual register figures
A10: Media Format – video orientation and duration (values)
A11: Please note that branding only is old name for minimal+repetitive, left unchanged due to linking issues
A12: By Account – Appendix B disaggregation by account and robustness checks
... A18: Accounts
A19: account | B19: label | C19: n_posts_corpus | D19: party | E19: n_ai_full_corpus | F19: country_name
A20: AU_onenationoz | B20: One Nation | C20: =COUNTIF(acct,$A20) -> 428 | D20: One Nation | E20: =COUNTIFS(acct,$A20,ai_full,1) -> 0 | F20: Australia
A21: AU_senatorpaulinehanson | B21: Hanson | C21: =COUNTIF(acct,$A21) -> 21 | D21: One Nation | E21: =COUNTIFS(acct,$A21,ai_full,1) -> 0 | F21: Australia
A22: BE_EU_vlaamsbelang | B22: Vlaams Belang | C22: =COUNTIF(acct,$A22) -> 183 | D22: VB | E22: =COUNTIFS(acct,$A22,ai_full,1) -> 3 | F22: Belgium
A23: BE_EU-vangriekentom | B23: Van Grieken | C23: =COUNTIF(acct,$A23) -> 237 | D23: VB | E23: =COUNTIFS(acct,$A23,ai_full,1) -> 0 | F23: Belgium
A24: DE_afd.bund | B24: AfD | C24: =COUNTIF(acct,$A24) -> 185 | D24: AfD | E24: =COUNTIFS(acct,$A24,ai_full,1) -> 56 | F24: Germany
A25: DE_alice.weidel | B25: Weidel | C25: =COUNTIF(acct,$A25) -> 309 | D25: AfD | E25: =COUNTIFS(acct,$A25,ai_full,1) -> 15 | F25: Germany
A26: DK-EU_dansk_folkeparti_1995_ | B26: Dansk Folkeparti | C26: =COUNTIF(acct,$A26) -> 202 | D26: DF | E26: =COUNTIFS(acct,$A26,ai_full,1) -> 5 | F26: Denmark
A27: DK-EU_mrmesserschmidt | B27: Messerschmidt | C27: =COUNTIF(acct,$A27) -> 219 | D27: DF | E27: =COUNTIFS(acct,$A27,ai_full,1) -> 6 | F27: Denmark
A28: ES-EU_vox_es | B28: VOX | C28: =COUNTIF(acct,$A28) -> 722 | D28: VOX | E28: =COUNTIFS(acct,$A28,ai_full,1) -> 37 | F28: Spain
A29: ES-EU_santi_abascal | B29: Abascal | C29: =COUNTIF(acct,$A29) -> 288 | D29: VOX | E29: =COUNTIFS(acct,$A29,ai_full,1) -> 4 | F29: Spain
A30: FR_EU_rassemblementnational_fr | B30: RN | C30: =COUNTIF(acct,$A30) -> 1226 | D30: RN | E30: =COUNTIFS(acct,$A30,ai_full,1) -> 24 | F30: France
A31: FR_EU_jordanbardella | B31: Bardella | C31: =COUNTIF(acct,$A31) -> 114 | D31: RN | E31: =COUNTIFS(acct,$A31,ai_full,1) -> 0 | F31: France
... A38: UK_nigel_farage | B38: Farage | C38: =COUNTIF(acct,$A38) -> 102 | D38: Reform UK | E38: =COUNTIFS(acct,$A38,ai_full,1) -> 0 | F38: UK
A39: Total
A43: Topic layer
A44: code | B44: label
A45: IMM | B45: Immigration
A46: ISL | B46: Islam
A47: CRI | B47: Crime & security
A48: SOV | B48: Sovereignty & identity
A49: ECON | B49: Economy & services
A50: LAND | B50: Land & environment
A51: CULT | B51: Gender & culture
A52: DEF | B52: Defence & foreign

Sheet Posts
A1: Post | F1: AI status and duplicates | I1: Theme codes | Q1: Sample | R1: Flags (formulas)
A2: i | B2: account | C2: country | D2: date | E2: pid | F2: ai_status | G2: ai_seq | H2: dup_of | I2: IMM | J2: ISL | K2: CRI | L2: SOV | M2: ECON | N2: LAND | O2: CULT | P2: DEF | Q2: in_sample | R2: is_ai | S2: is_conv | T2: n_topics | U2: topical | V2: ai_full
A3: 0 | B3: AU_onenationoz | C3: AU | D3: 45670 | E3: 2025-01-13_(1) | F3: conventional | Q3: 0 | R3: =IF(AND(Q3=1,F3="ai_full"),1,0) -> 0 | S3: =IF(AND(Q3=1,F3="conventional"),1,0) -> 0 | T3: =SUM(I3:P3) -> 0 | U3: =IF(T3>=1,1,0) -> 0 | V3: =IF(F3="ai_full",1,0) -> 0
A4: 1 | B4: AU_onenationoz | C4: AU | D4: 45670 | E4: 2025-01-13_(2) | F4: conventional | I4: 0 | J4: 0 | K4: 0 | L4: 1 | M4: 0 | N4: 0 | O4: 0 | P4: 0 | Q4: 1 | R4: =IF(AND(Q4=1,F4="ai_full"),1,0) -> 0 | S4: =IF(AND(Q4=1,F4="conventional"),1,0) -> 1 | T4: =SUM(I4:P4) -> 1 | U4: =IF(T4>=1,1,0) -> 1 | V4: =IF(F4="ai_full",1,0) -> 0
A5: 2 | B5: AU_onenationoz | C5: AU | D5: 45670 | E5: 2025-01-13_(3) | F5: conventional | I5: 0 | J5: 0 | K5: 0 | L5: 1 | M5: 0 | N5: 0 | O5: 0 | P5: 0 | Q5: 1 | R5: =IF(AND(Q5=1,F5="ai_full"),1,0) -> 0 | S5: =IF(AND(Q5=1,F5="conventional"),1,0) -> 1 | T5: =SUM(I5:P5) -> 1 | U5: =IF(T5>=1,1,0) -> 1 | V5: =IF(F5="ai_full",1,0) -> 0
A6: 3 | B6: AU_onenationoz | C6: AU | D6: 45670 | E6: 2025-01-13_(4) | F6: conventional | Q6: 0 | R6: =IF(AND(Q6=1,F6="ai_full"),1,0) -> 0 | S6: =IF(AND(Q6=1,F6="conventional"),1,0) -> 0 | T6: =SUM(I6:P6) -> 0 | U6: =IF(T6>=1,1,0) -> 0 | V6: =IF(F6="ai_full",1,0) -> 0
A7: 4 | B7: AU_onenationoz | C7: AU | D7: 45671 | E7: 2025-01-14_(1) | F7: conventional | I7: 0 | J7: 0 | K7: 0 | L7: 0 | M7: 1 | N7: 1 | O7: 0 | P7: 0 | Q7: 1 | R7: =IF(AND(Q7=1,F7="ai_full"),1,0) -> 0 | S7: =IF(AND(Q7=1,F7="conventional"),1,0) -> 1 | T7: =SUM(I7:P7) -> 2 | U7: =IF(T7>=1,1,0) -> 1 | V7: =IF(F7="ai_full",1,0) -> 0
A8: 5 | B8: AU_onenationoz | C8: AU | D8: 45671 | E8: 2025-01-14_(2) | F8: conventional | I8: 0 | J8: 0 | K8: 0 | L8: 0 | M8: 0 | N8: 0 | O8: 0 | P8: 0 | Q8: 1 | R8: =IF(AND(Q8=1,F8="ai_full"),1,0) -> 0 | S8: =IF(AND(Q8=1,F8="conventional"),1,0) -> 1 | T8: =SUM(I8:P8) -> 0 | U8: =IF(T8>=1,1,0) -> 0 | V8: =IF(F8="ai_full",1,0) -> 0
A9: 6 | B9: AU_onenationoz | C9: AU | D9: 45672 | E9: 2025-01-15_(1) | F9: conventional | I9: 0 | J9: 0 | K9: 0 | L9: 1 | M9: 0 | N9: 0 | O9: 0 | P9: 0 | Q9: 1 | R9: =IF(AND(Q9=1,F9="ai_full"),1,0) -> 0 | S9: =IF(AND(Q9=1,F9="conventional"),1,0) -> 1 | T9: =SUM(I9:P9) -> 1 | U9: =IF(T9>=1,1,0) -> 1 | V9: =IF(F9="ai_full",1,0) -> 0
A10: 7 | B10: AU_onenationoz | C10: AU | D10: 45672 | E10: 2025-01-15_(2) | F10: conventional | I10: 0 | J10: 0 | K10: 0 | L10: 0 | M10: 0 | N10: 0 | O10: 0 | P10: 0 | Q10: 1 | R10: =IF(AND(Q10=1,F10="ai_full"),1,0) -> 0 | S10: =IF(AND(Q10=1,F10="conventional"),1,0) -> 1 | T10: =SUM(I10:P10) -> 0 | U10: =IF(T10>=1,1,0) -> 0 | V10: =IF(F10="ai_full",1,0) -> 0
A11: 8 | B11: AU_onenationoz | C11: AU | D11: 45672 | E11: 2025-01-15_(3) | F11: conventional | I11: 0 | J11: 0 | K11: 0 | L11: 0 | M11: 1 | N11: 0 | O11: 0 | P11: 0 | Q11: 1 | R11: =IF(AND(Q11=1,F11="ai_full"),1,0) -> 0 | S11: =IF(AND(Q11=1,F11="conventional"),1,0) -> 1 | T11: =SUM(I11:P11) -> 1 | U11: =IF(T11>=1,1,0) -> 1 | V11: =IF(F11="ai_full",1,0) -> 0
A12: 9 | B12: AU_onenationoz | C12: AU | D12: 45673 | E12: 2025-01-16_(1) | F12: conventional | I12: 0 | J12: 0 | K12: 0 | L12: 1 | M12: 0 | N12: 0 | O12: 0 | P12: 0 | Q12: 1 | R12: =IF(AND(Q12=1,F12="ai_full"),1,0) -> 0 | S12: =IF(AND(Q12=1,F12="conventional"),1,0) -> 1 | T12: =SUM(I12:P12) -> 1 | U12: =IF(T12>=1,1,0) -> 1 | V12: =IF(F12="ai_full",1,0) -> 0
A13: 10 | B13: AU_onenationoz | C13: AU | D13: 45673 | E13: 2025-01-16_(2) | F13: conventional | Q13: 0 | R13: =IF(AND(Q13=1,F13="ai_full"),1,0) -> 0 | S13: =IF(AND(Q13=1,F13="conventional"),1,0) -> 0 | T13: =SUM(I13:P13) -> 0 | U13: =IF(T13>=1,1,0) -> 0 | V13: =IF(F13="ai_full",1,0) -> 0
A14: 11 | B14: AU_onenationoz | C14: AU | D14: 45673 | E14: 2025-01-16_(3) | F14: conventional | I14: 0 | J14: 0 | K14: 0 | L14: 0 | M14: 0 | N14: 0 | O14: 0 | P14: 0 | Q14: 1 | R14: =IF(AND(Q14=1,F14="ai_full"),1,0) -> 0 | S14: =IF(AND(Q14=1,F14="conventional"),1,0) -> 1 | T14: =SUM(I14:P14) -> 0 | U14: =IF(T14>=1,1,0) -> 0 | V14: =IF(F14="ai_full",1,0) -> 0
A15: 12 | B15: AU_onenationoz | C15: AU | D15: 45673 | E15: 2025-01-16_(4) | F15: conventional | I15: 0 | J15: 0 | K15: 0 | L15: 0 | M15: 0 | N15: 0 | O15: 0 | P15: 0 | Q15: 1 | R15: =IF(AND(Q15=1,F15="ai_full"),1,0) -> 0 | S15: =IF(AND(Q15=1,F15="conventional"),1,0) -> 1 | T15: =SUM(I15:P15) -> 0 | U15: =IF(T15>=1,1,0) -> 0 | V15: =IF(F15="ai_full",1,0) -> 0
A16: 13 | B16: AU_onenationoz | C16: AU | D16: 45674 | E16: 2025-01-17_(1) | F16: conventional | Q16: 0 | R16: =IF(AND(Q16=1,F16="ai_full"),1,0) -> 0 | S16: =IF(AND(Q16=1,F16="conventional"),1,0) -> 0 | T16: =SUM(I16:P16) -> 0 | U16: =IF(T16>=1,1,0) -> 0 | V16: =IF(F16="ai_full",1,0) -> 0
A17: 14 | B17: AU_onenationoz | C17: AU | D17: 45674 | E17: 2025-01-17_(2) | F17: conventional | I17: 0 | J17: 0 | K17: 0 | L17: 0 | M17: 0 | N17: 0 | O17: 0 | P17: 0 | Q17: 1 | R17: =IF(AND(Q17=1,F17="ai_full"),1,0) -> 0 | S17: =IF(AND(Q17=1,F17="conventional"),1,0) -> 1 | T17: =SUM(I17:P17) -> 0 | U17: =IF(T17>=1,1,0) -> 0 | V17: =IF(F17="ai_full",1,0) -> 0
A18: 15 | B18: AU_onenationoz | C18: AU | D18: 45674 | E18: 2025-01-17_(3) | F18: conventional | I18: 0 | J18: 0 | K18: 0 | L18: 0 | M18: 0 | N18: 0 | O18: 0 | P18: 0 | Q18: 1 | R18: =IF(AND(Q18=1,F18="ai_full"),1,0) -> 0 | S18: =IF(AND(Q18=1,F18="conventional"),1,0) -> 1 | T18: =SUM(I18:P18) -> 0 | U18: =IF(T18>=1,1,0) -> 0 | V18: =IF(F18="ai_full",1,0) -> 0
A19: 16 | B19: AU_onenationoz | C19: AU | D19: 45674 | E19: 2025-01-17_(4) | F19: conventional | Q19: 0 | R19: =IF(AND(Q19=1,F19="ai_full"),1,0) -> 0 | S19: =IF(AND(Q19=1,F19="conventional"),1,0) -> 0 | T19: =SUM(I19:P19) -> 0 | U19: =IF(T19>=1,1,0) -> 0 | V19: =IF(F19="ai_full",1,0) -> 0
A20: 17 | B20: AU_onenationoz | C20: AU | D20: 45674 | E20: 2025-01-17_(5) | F20: conventional | Q20: 0 | R20: =IF(AND(Q20=1,F20="ai_full"),1,0) -> 0 | S20: =IF(AND(Q20=1,F20="conventional"),1,0) -> 0 | T20: =SUM(I20:P20) -> 0 | U20: =IF(T20>=1,1,0) -> 0 | V20: =IF(F20="ai_full",1,0) -> 0
A21: 18 | B21: AU_onenationoz | C21: AU | D21: 45674 | E21: 2025-01-17_(6) | F21: conventional | I21: 0 | J21: 0 | K21: 0 | L21: 0 | M21: 1 | N21: 0 | O21: 0 | P21: 0 | Q21: 1 | R21: =IF(AND(Q21=1,F21="ai_full"),1,0) -> 0 | S21: =IF(AND(Q21=1,F21="conventional"),1,0) -> 1 | T21: =SUM(I21:P21) -> 1 | U21: =IF(T21>=1,1,0) -> 1 | V21: =IF(F21="ai_full",1,0) -> 0
A22: 19 | B22: AU_onenationoz | C22: AU | D22: 45674 | E22: 2025-01-17_(7) | F22: conventional | I22: 0 | J22: 0 | K22: 0 | L22: 0 | M22: 1 | N22: 0 | O22: 0 | P22: 0 | Q22: 1 | R22: =IF(AND(Q22=1,F22="ai_full"),1,0) -> 0 | S22: =IF(AND(Q22=1,F22="conventional"),1,0) -> 1 | T22: =SUM(I22:P22) -> 1 | U22: =IF(T22>=1,1,0) -> 1 | V22: =IF(F22="ai_full",1,0) -> 0
A23: 20 | B23: AU_onenationoz | C23: AU | D23: 45675 | E23: 2025-01-18_(1) | F23: conventional | I23: 0 | J23: 0 | K23: 0 | L23: 0 | M23: 0 | N23: 0 | O23: 0 | P23: 0 | Q23: 1 | R23: =IF(AND(Q23=1,F23="ai_full"),1,0) -> 0 | S23: =IF(AND(Q23=1,F23="conventional"),1,0) -> 1 | T23: =SUM(I23:P23) -> 0 | U23: =IF(T23>=1,1,0) -> 0 | V23: =IF(F23="ai_full",1,0) -> 0
A24: 21 | B24: AU_onenationoz | C24: AU | D24: 45675 | E24: 2025-01-18_(2) | F24: conventional | I24: 0 | J24: 0 | K24: 0 | L24: 0 | M24: 0 | N24: 0 | O24: 0 | P24: 0 | Q24: 1 | R24: =IF(AND(Q24=1,F24="ai_full"),1,0) -> 0 | S24: =IF(AND(Q24=1,F24="conventional"),1,0) -> 1 | T24: =SUM(I24:P24) -> 0 | U24: =IF(T24>=1,1,0) -> 0 | V24: =IF(F24="ai_full",1,0) -> 0
A25: 22 | B25: AU_onenationoz | C25: AU | D25: 45677 | E25: 2025-01-20_(1) | F25: conventional | I25: 0 | J25: 0 | K25: 0 | L25: 1 | M25: 0 | N25: 0 | O25: 0 | P25: 0 | Q25: 1 | R25: =IF(AND(Q25=1,F25="ai_full"),1,0) -> 0 | S25: =IF(AND(Q25=1,F25="conventional"),1,0) -> 1 | T25: =SUM(I25:P25) -> 1 | U25: =IF(T25>=1,1,0) -> 1 | V25: =IF(F25="ai_full",1,0) -> 0
A26: 23 | B26: AU_onenationoz | C26: AU | D26: 45677 | E26: 2025-01-20_(2) | F26: conventional | I26: 0 | J26: 0 | K26: 0 | L26: 0 | M26: 1 | N26: 1 | O26: 0 | P26: 0 | Q26: 1 | R26: =IF(AND(Q26=1,F26="ai_full"),1,0) -> 0 | S26: =IF(AND(Q26=1,F26="conventional"),1,0) -> 1 | T26: =SUM(I26:P26) -> 2 | U26: =IF(T26>=1,1,0) -> 1 | V26: =IF(F26="ai_full",1,0) -> 0
A27: 24 | B27: AU_onenationoz | C27: AU | D27: 45677 | E27: 2025-01-20_(3) | F27: conventional | I27: 0 | J27: 0 | K27: 0 | L27: 0 | M27: 0 | N27: 0 | O27: 0 | P27: 0 | Q27: 1 | R27: =IF(AND(Q27=1,F27="ai_full"),1,0) -> 0 | S27: =IF(AND(Q27=1,F27="conventional"),1,0) -> 1 | T27: =SUM(I27:P27) -> 0 | U27: =IF(T27>=1,1,0) -> 0 | V27: =IF(F27="ai_full",1,0) -> 0
A28: 25 | B28: AU_onenationoz | C28: AU | D28: 45678 | E28: 2025-01-21_(1) | F28: conventional | I28: 0 | J28: 0 | K28: 0 | L28: 0 | M28: 0 | N28: 0 | O28: 0 | P28: 0 | Q28: 1 | R28: =IF(AND(Q28=1,F28="ai_full"),1,0) -> 0 | S28: =IF(AND(Q28=1,F28="conventional"),1,0) -> 1 | T28: =SUM(I28:P28) -> 0 | U28: =IF(T28>=1,1,0) -> 0 | V28: =IF(F28="ai_full",1,0) -> 0
A29: 26 | B29: AU_onenationoz | C29: AU | D29: 45678 | E29: 2025-01-21_(2) | F29: conventional | Q29: 0 | R29: =IF(AND(Q29=1,F29="ai_full"),1,0) -> 0 | S29: =IF(AND(Q29=1,F29="conventional"),1,0) -> 0 | T29: =SUM(I29:P29) -> 0 | U29: =IF(T29>=1,1,0) -> 0 | V29: =IF(F29="ai_full",1,0) -> 0
A30: 27 | B30: AU_onenationoz | C30: AU | D30: 45678 | E30: 2025-01-21_(3) | F30: conventional | I30: 1 | J30: 0 | K30: 0 | L30: 0 | M30: 1 | N30: 0 | O30: 1 | P30: 0 | Q30: 1 | R30: =IF(AND(Q30=1,F30="ai_full"),1,0) -> 0 | S30: =IF(AND(Q30=1,F30="conventional"),1,0) -> 1 | T30: =SUM(I30:P30) -> 3 | U30: =IF(T30>=1,1,0) -> 1 | V30: =IF(F30="ai_full",1,0) -> 0
A31: 28 | B31: AU_onenationoz | C31: AU | D31: 45678 | E31: 2025-01-21_(4) | F31: conventional | Q31: 0 | R31: =IF(AND(Q31=1,F31="ai_full"),1,0) -> 0 | S31: =IF(AND(Q31=1,F31="conventional"),1,0) -> 0 | T31: =SUM(I31:P31) -> 0 | U31: =IF(T31>=1,1,0) -> 0 | V31: =IF(F31="ai_full",1,0) -> 0
A32: 29 | B32: AU_onenationoz | C32: AU | D32: 45678 | E32: 2025-01-21_(5) | F32: conventional | I32: 1 | J32: 0 | K32: 0 | L32: 0 | M32: 1 | N32: 0 | O32: 0 | P32: 1 | Q32: 1 | R32: =IF(AND(Q32=1,F32="ai_full"),1,0) -> 0 | S32: =IF(AND(Q32=1,F32="conventional"),1,0) -> 1 | T32: =SUM(I32:P32) -> 3 | U32: =IF(T32>=1,1,0) -> 1 | V32: =IF(F32="ai_full",1,0) -> 0
A33: 30 | B33: AU_onenationoz | C33: AU | D33: 45679 | E33: 2025-01-22_(1) | F33: conventional | Q33: 0 | R33: =IF(AND(Q33=1,F33="ai_full"),1,0) -> 0 | S33: =IF(AND(Q33=1,F33="conventional"),1,0) -> 0 | T33: =SUM(I33:P33) -> 0 | U33: =IF(T33>=1,1,0) -> 0 | V33: =IF(F33="ai_full",1,0) -> 0
A34: 31 | B34: AU_onenationoz | C34: AU | D34: 45679 | E34: 2025-01-22_(2) | F34: conventional | Q34: 0 | R34: =IF(AND(Q34=1,F34="ai_full"),1,0) -> 0 | S34: =IF(AND(Q34=1,F34="conventional"),1,0) -> 0 | T34: =SUM(I34:P34) -> 0 | U34: =IF(T34>=1,1,0) -> 0 | V34: =IF(F34="ai_full",1,0) -> 0
A35: 32 | B35: AU_onenationoz | C35: AU | D35: 45679 | E35: 2025-01-22_(3) | F35: conventional | I35: 0 | J35: 0 | K35: 1 | L35: 0 | M35: 1 | N35: 0 | O35: 0 | P35: 0 | Q35: 1 | R35: =IF(AND(Q35=1,F35="ai_full"),1,0) -> 0 | S35: =IF(AND(Q35=1,F35="conventional"),1,0) -> 1 | T35: =SUM(I35:P35) -> 2 | U35: =IF(T35>=1,1,0) -> 1 | V35: =IF(F35="ai_full",1,0) -> 0
A36: 33 | B36: AU_onenationoz | C36: AU | D36: 45679 | E36: 2025-01-22_(4) | F36: conventional | I36: 0 | J36: 0 | K36: 0 | L36: 0 | M36: 1 | N36: 0 | O36: 0 | P36: 0 | Q36: 1 | R36: =IF(AND(Q36=1,F36="ai_full"),1,0) -> 0 | S36: =IF(AND(Q36=1,F36="conventional"),1,0) -> 1 | T36: =SUM(I36:P36) -> 1 | U36: =IF(T36>=1,1,0) -> 1 | V36: =IF(F36="ai_full",1,0) -> 0
A37: 34 | B37: AU_onenationoz | C37: AU | D37: 45679 | E37: 2025-01-22_(5) | F37: conventional | Q37: 0 | R37: =IF(AND(Q37=1,F37="ai_full"),1,0) -> 0 | S37: =IF(AND(Q37=1,F37="conventional"),1,0) -> 0 | T37: =SUM(I37:P37) -> 0 | U37: =IF(T37>=1,1,0) -> 0 | V37: =IF(F37="ai_full",1,0) -> 0
A38: 35 | B38: AU_onenationoz | C38: AU | D38: 45680 | E38: 2025-01-23_(1) | F38: conventional | I38: 0 | J38: 0 | K38: 1 | L38: 0 | M38: 1 | N38: 0 | O38: 0 | P38: 0 | Q38: 1 | R38: =IF(AND(Q38=1,F38="ai_full"),1,0) -> 0 | S38: =IF(AND(Q38=1,F38="conventional"),1,0) -> 1 | T38: =SUM(I38:P38) -> 2 | U38: =IF(T38>=1,1,0) -> 1 | V38: =IF(F38="ai_full",1,0) -> 0
A39: 36 | B39: AU_onenationoz | C39: AU | D39: 45680 | E39: 2025-01-23_(2) | F39: conventional | I39: 1 | J39: 0 | K39: 0 | L39: 1 | M39: 1 | N39: 1 | O39: 1 | P39: 0 | Q39: 1 | R39: =IF(AND(Q39=1,F39="ai_full"),1,0) -> 0 | S39: =IF(AND(Q39=1,F39="conventional"),1,0) -> 1 | T39: =SUM(I39:P39) -> 5 | U39: =IF(T39>=1,1,0) -> 1 | V39: =IF(F39="ai_full",1,0) -> 0
A40: 37 | B40: AU_onenationoz | C40: AU | D40: 45680 | E40: 2025-01-23_(3) | F40: conventional | Q40: 0 | R40: =IF(AND(Q40=1,F40="ai_full"),1,0) -> 0 | S40: =IF(AND(Q40=1,F40="conventional"),1,0) -> 0 | T40: =SUM(I40:P40) -> 0 | U40: =IF(T40>=1,1,0) -> 0 | V40: =IF(F40="ai_full",1,0) -> 0
...

Sheet Themes
A1: T1 – Topic shares: AI (full visuals) vs conventional posts, whole corpus
A2: Share = posts with the topic / sampled posts of that status; a post can carry several topics. Chi-square: Pearson 1 df, no continuity correction; flagged where an expected cell < 5.
A4: N AI | B4: =SUMPRODUCT(is_ai) -> 217
A5: N conv | B5: =SUMPRODUCT(is_conv) -> 3742 | P5: Standardised = conventional share weighted to the AI side's account mix (within-party gap); pooled F/G for reference.
A7: code | B7: label | C7: n AI | D7: n conv | E7: share AI | F7: share conv | G7: diff (pp) | H7: ratio AI/conv | I7: χ² | J7: p | K7: min expected | L7: small-cell flag | M7: sort key | N7: rank | P7: share conv, standardised to AI account mix | Q7: diff standardised (pp)
A8: IMM | B8: =README!$B$45 -> Immigration | C8: =SUMPRODUCT(is_ai,T_IMM) -> 79 | D8: =SUMPRODUCT(is_conv,T_IMM) -> 832 | E8: =IF($B$4>0,C8/$B$4,0) -> 0.3640553 | F8: =IF($B$5>0,D8/$B$5,0) -> 0.22234099 | G8: =(E8-F8)*100 -> 14.171431 | H8: =IF(F8>0,E8/F8,"") -> 1.6373737 | I8: =IFERROR(($B$4+$B$5)*(C8*($B$5-D8)-($B$4-C8)*D8)^2/($B$4*$B$5*(C8+D8)*(($B$4-C8)+($B$5-D8))),"") -> 23.251076 | J8: =IF(I8="","",_xlfn.CHISQ.DIST.RT(I8,1)) -> 1.4217085e-06 | K8: =IFERROR(MIN($B$4,$B$5)*MIN(C8+D8,($B$4-C8)+($B$5-D8))/($B$4+$B$5),"") -> 49.933569 | L8: =IF(K8="","",IF(K8<5,"expected < 5","")) | M8: =F8+ROW()/1000000 -> 0.22234899 | N8: =RANK(M8,$M$8:$M$15,0) -> 3 | P8: =SUMPRODUCT(COUNTIFS(acct,acc_tbl,is_conv,1,T_IMM,1)/COUNTIFS(acct,acc_tbl,is_conv,1),COUNTIFS(acct,acc_tbl,is_ai,1))/$B$4 -> 0.2487313 | Q8: =(E8-P8)*100 -> 11.5324
A9: ISL | B9: =README!$B$46 -> Islam | C9: =SUMPRODUCT(is_ai,T_ISL) -> 29 | D9: =SUMPRODUCT(is_conv,T_ISL) -> 132 | E9: =IF($B$4>0,C9/$B$4,0) -> 0.13364055 | F9: =IF($B$5>0,D9/$B$5,0) -> 0.035275254 | G9: =(E9-F9)*100 -> 9.8365299 | H9: =IF(F9>0,E9/F9,"") -> 3.7885072 | I9: =IFERROR(($B$4+$B$5)*(C9*($B$5-D9)-($B$4-C9)*D9)^2/($B$4*$B$5*(C9+D9)*(($B$4-C9)+($B$5-D9))),"") -> 50.868861 | J9: =IF(I9="","",_xlfn.CHISQ.DIST.RT(I9,1)) -> 9.8747793e-13 | K9: =IFERROR(MIN($B$4,$B$5)*MIN(C9+D9,($B$4-C9)+($B$5-D9))/($B$4+$B$5),"") -> 8.8247032 | L9: =IF(K9="","",IF(K9<5,"expected < 5","")) | M9: =F9+ROW()/1000000 -> 0.035284254 | N9: =RANK(M9,$M$8:$M$15,0) -> 8 | P9: =SUMPRODUCT(COUNTIFS(acct,acc_tbl,is_conv,1,T_ISL,1)/COUNTIFS(acct,acc_tbl,is_conv,1),COUNTIFS(acct,acc_tbl,is_ai,1))/$B$4 -> 0.043672602 | Q9: =(E9-P9)*100 -> 8.9967951
A10: CRI | B10: =README!$B$47 -> Crime & security | C10: =SUMPRODUCT(is_ai,T_CRI) -> 50 | D10: =SUMPRODUCT(is_conv,T_CRI) -> 606 | E10: =IF($B$4>0,C10/$B$4,0) -> 0.23041475 | F10: =IF($B$5>0,D10/$B$5,0) -> 0.16194548 | G10: =(E10-F10)*100 -> 6.8469263 | H10: =IF(F10>0,E10/F10,"") -> 1.422792 | I10: =IFERROR(($B$4+$B$5)*(C10*($B$5-D10)-($B$4-C10)*D10)^2/($B$4*$B$5*(C10+D10)*(($B$4-C10)+($B$5-D10))),"") -> 6.9554929 | J10: =IF(I10="","",_xlfn.CHISQ.DIST.RT(I10,1)) -> 0.0083562275 | K10: =IFERROR(MIN($B$4,$B$5)*MIN(C10+D10,($B$4-C10)+($B$5-D10))/($B$4+$B$5),"") -> 35.956555 | L10: =IF(K10="","",IF(K10<5,"expected < 5","")) | M10: =F10+ROW()/1000000 -> 0.16195548 | N10: =RANK(M10,$M$8:$M$15,0) -> 4 | P10: =SUMPRODUCT(COUNTIFS(acct,acc_tbl,is_conv,1,T_CRI,1)/COUNTIFS(acct,acc_tbl,is_conv,1),COUNTIFS(acct,acc_tbl,is_ai,1))/$B$4 -> 0.19322331 | Q10: =(E10-P10)*100 -> 3.7191432
A11: SOV | B11: =README!$B$48 -> Sovereignty & identity | C11: =SUMPRODUCT(is_ai,T_SOV) -> 55 | D11: =SUMPRODUCT(is_conv,T_SOV) -> 987 | E11: =IF($B$4>0,C11/$B$4,0) -> 0.25345622 | F11: =IF($B$5>0,D11/$B$5,0) -> 0.26376269 | G11: =(E11-F11)*100 -> -1.0306473 | H11: =IF(F11>0,E11/F11,"") -> 0.96092521 | I11: =IFERROR(($B$4+$B$5)*(C11*($B$5-D11)-($B$4-C11)*D11)^2/($B$4*$B$5*(C11+D11)*(($B$4-C11)+($B$5-D11))),"") -> 0.1123479 | J11: =IF(I11="","",_xlfn.CHISQ.DIST.RT(I11,1)) -> 0.73748675 | K11: =IFERROR(MIN($B$4,$B$5)*MIN(C11+D11,($B$4-C11)+($B$5-D11))/($B$4+$B$5),"") -> 57.113918 | L11: =IF(K11="","",IF(K11<5,"expected < 5","")) | M11: =F11+ROW()/1000000 -> 0.26377369 | N11: =RANK(M11,$M$8:$M$15,0) -> 1 | P11: =SUMPRODUCT(COUNTIFS(acct,acc_tbl,is_conv,1,T_SOV,1)/COUNTIFS(acct,acc_tbl,is_conv,1),COUNTIFS(acct,acc_tbl,is_ai,1))/$B$4 -> 0.23533093 | Q11: =(E11-P11)*100 -> 1.8125293
A12: ECON | B12: =README!$B$49 -> Economy & services | C12: =SUMPRODUCT(is_ai,T_ECON) -> 68 | D12: =SUMPRODUCT(is_conv,T_ECON) -> 943 | E12: =IF($B$4>0,C12/$B$4,0) -> 0.31336406 | F12: =IF($B$5>0,D12/$B$5,0) -> 0.25200428 | G12: =(E12-F12)*100 -> 6.135978 | H12: =IF(F12>0,E12/F12,"") -> 1.2434871 | I12: =IFERROR(($B$4+$B$5)*(C12*($B$5-D12)-($B$4-C12)*D12)^2/($B$4*$B$5*(C12+D12)*(($B$4-C12)+($B$5-D12))),"") -> 4.0610465 | J12: =IF(I12="","",_xlfn.CHISQ.DIST.RT(I12,1)) -> 0.043883295 | K12: =IFERROR(MIN($B$4,$B$5)*MIN(C12+D12,($B$4-C12)+($B$5-D12))/($B$4+$B$5),"") -> 55.414751 | L12: =IF(K12="","",IF(K12<5,"expected < 5","")) | M12: =F12+ROW()/1000000 -> 0.25201628 | N12: =RANK(M12,$M$8:$M$15,0) -> 2 | P12: =SUMPRODUCT(COUNTIFS(acct,acc_tbl,is_conv,1,T_ECON,1)/COUNTIFS(acct,acc_tbl,is_conv,1),COUNTIFS(acct,acc_tbl,is_ai,1))/$B$4 -> 0.2488866 | Q12: =(E12-P12)*100 -> 6.4477457
A13: LAND | B13: =README!$B$50 -> Land & environment | C13: =SUMPRODUCT(is_ai,T_LAND) -> 33 | D13: =SUMPRODUCT(is_conv,T_LAND) -> 441 | E13: =IF($B$4>0,C13/$B$4,0) -> 0.15207373 | F13: =IF($B$5>0,D13/$B$5,0) -> 0.11785142 | G13: =(E13-F13)*100 -> 3.4222316 | H13: =IF(F13>0,E13/F13,"") -> 1.2903853 | I13: =IFERROR(($B$4+$B$5)*(C13*($B$5-D13)-($B$4-C13)*D13)^2/($B$4*$B$5*(C13+D13)*(($B$4-C13)+($B$5-D13))),"") -> 2.2792224 | J13: =IF(I13="","",_xlfn.CHISQ.DIST.RT(I13,1)) -> 0.1311176 | K13: =IFERROR(MIN($B$4,$B$5)*MIN(C13+D13,($B$4-C13)+($B$5-D13))/($B$4+$B$5),"") -> 25.980803 | L13: =IF(K13="","",IF(K13<5,"expected < 5","")) | M13: =F13+ROW()/1000000 -> 0.11786442 | N13: =RANK(M13,$M$8:$M$15,0) -> 5 | P13: =SUMPRODUCT(COUNTIFS(acct,acc_tbl,is_conv,1,T_LAND,1)/COUNTIFS(acct,acc_tbl,is_conv,1),COUNTIFS(acct,acc_tbl,is_ai,1))/$B$4 -> 0.15373176 | Q13: =(E13-P13)*100 -> -0.16580273
A14: CULT | B14: =README!$B$51 -> Gender & culture | C14: =SUMPRODUCT(is_ai,T_CULT) -> 34 | D14: =SUMPRODUCT(is_conv,T_CULT) -> 219 | E14: =IF($B$4>0,C14/$B$4,0) -> 0.15668203 | F14: =IF($B$5>0,D14/$B$5,0) -> 0.058524853 | G14: =(E14-F14)*100 -> 9.8157175 | H14: =IF(F14>0,E14/F14,"") -> 2.6771879 | I14: =IFERROR(($B$4+$B$5)*(C14*($B$5-D14)-($B$4-C14)*D14)^2/($B$4*$B$5*(C14+D14)*(($B$4-C14)+($B$5-D14))),"") -> 33.034458 | J14: =IF(I14="","",_xlfn.CHISQ.DIST.RT(I14,1)) -> 9.0539932e-09 | K14: =IFERROR(MIN($B$4,$B$5)*MIN(C14+D14,($B$4-C14)+($B$5-D14))/($B$4+$B$5),"") -> 13.867391 | L14: =IF(K14="","",IF(K14<5,"expected < 5","")) | M14: =F14+ROW()/1000000 -> 0.058538853 | N14: =RANK(M14,$M$8:$M$15,0) -> 6 | P14: =SUMPRODUCT(COUNTIFS(acct,acc_tbl,is_conv,1,T_CULT,1)/COUNTIFS(acct,acc_tbl,is_conv,1),COUNTIFS(acct,acc_tbl,is_ai,1))/$B$4 -> 0.072717902 | Q14: =(E14-P14)*100 -> 8.3964125
A15: DEF | B15: =README!$B$52 -> Defence & foreign | C15: =SUMPRODUCT(is_ai,T_DEF) -> 14 | D15: =SUMPRODUCT(is_conv,T_DEF) -> 151 | E15: =IF($B$4>0,C15/$B$4,0) -> 0.064516129 | F15: =IF($B$5>0,D15/$B$5,0) -> 0.040352753 | G15: =(E15-F15)*100 -> 2.4163376 | H15: =IF(F15>0,E15/F15,"") -> 1.5988037 | I15: =IFERROR(($B$4+$B$5)*(C15*($B$5-D15)-($B$4-C15)*D15)^2/($B$4*$B$5*(C15+D15)*(($B$4-C15)+($B$5-D15))),"") -> 2.9983546 | J15: =IF(I15="","",_xlfn.CHISQ.DIST.RT(I15,1)) -> 0.083349127 | K15: =IFERROR(MIN($B$4,$B$5)*MIN(C15+D15,($B$4-C15)+($B$5-D15))/($B$4+$B$5),"") -> 9.0439505 | L15: =IF(K15="","",IF(K15<5,"expected < 5","")) | M15: =F15+ROW()/1000000 -> 0.040367753 | N15: =RANK(M15,$M$8:$M$15,0) -> 7 | P15: =SUMPRODUCT(COUNTIFS(acct,acc_tbl,is_conv,1,T_DEF,1)/COUNTIFS(acct,acc_tbl,is_conv,1),COUNTIFS(acct,acc_tbl,is_ai,1))/$B$4 -> 0.052166382 | Q15: =(E15-P15)*100 -> 1.2349747
A17: Sorted for the chart (by conventional share)
A18: rank | B18: label | C18: conv | D18: AI | E18: diff (pp) | F18: p
A19: 1 | B19: =INDEX($B$8:$B$15,MATCH(A19,$N$8:$N$15,0)) -> Sovereignty & identity | C19: =INDEX($F$8:$F$15,MATCH(A19,$N$8:$N$15,0)) -> 0.26376269 | D19: =INDEX($E$8:$E$15,MATCH(A19,$N$8:$N$15,0)) -> 0.25345622 | E19: =INDEX($G$8:$G$15,MATCH(A19,$N$8:$N$15,0)) -> -1.0306473 | F19: =INDEX($J$8:$J$15,MATCH(A19,$N$8:$N$15,0)) -> 0.73748675
A20: 2 | B20: =INDEX($B$8:$B$15,MATCH(A20,$N$8:$N$15,0)) -> Economy & services | C20: =INDEX($F$8:$F$15,MATCH(A20,$N$8:$N$15,0)) -> 0.25200428 | D20: =INDEX($E$8:$E$15,MATCH(A20,$N$8:$N$15,0)) -> 0.31336406 | E20: =INDEX($G$8:$G$15,MATCH(A20,$N$8:$N$15,0)) -> 6.135978 | F20: =INDEX($J$8:$J$15,MATCH(A20,$N$8:$N$15,0)) -> 0.043883295
A21: 3 | B21: =INDEX($B$8:$B$15,MATCH(A21,$N$8:$N$15,0)) -> Immigration | C21: =INDEX($F$8:$F$15,MATCH(A21,$N$8:$N$15,0)) -> 0.22234099 | D21: =INDEX($E$8:$E$15,MATCH(A21,$N$8:$N$15,0)) -> 0.3640553 | E21: =INDEX($G$8:$G$15,MATCH(A21,$N$8:$N$15,0)) -> 14.171431 | F21: =INDEX($J$8:$J$15,MATCH(A21,$N$8:$N$15,0)) -> 1.4217085e-06
A22: 4 | B22: =INDEX($B$8:$B$15,MATCH(A22,$N$8:$N$15,0)) -> Crime & security | C22: =INDEX($F$8:$F$15,MATCH(A22,$N$8:$N$15,0)) -> 0.16194548 | D22: =INDEX($E$8:$E$15,MATCH(A22,$N$8:$N$15,0)) -> 0.23041475 | E22: =INDEX($G$8:$G$15,MATCH(A22,$N$8:$N$15,0)) -> 6.8469263 | F22: =INDEX($J$8:$J$15,MATCH(A22,$N$8:$N$15,0)) -> 0.0083562275
A23: 5 | B23: =INDEX($B$8:$B$15,MATCH(A23,$N$8:$N$15,0)) -> Land & environment | C23: =INDEX($F$8:$F$15,MATCH(A23,$N$8:$N$15,0)) -> 0.11785142 | D23: =INDEX($E$8:$E$15,MATCH(A23,$N$8:$N$15,0)) -> 0.15207373 | E23: =INDEX($G$8:$G$15,MATCH(A23,$N$8:$N$15,0)) -> 3.4222316 | F23: =INDEX($J$8:$J$15,MATCH(A23,$N$8:$N$15,0)) -> 0.1311176
A24: 6 | B24: =INDEX($B$8:$B$15,MATCH(A24,$N$8:$N$15,0)) -> Gender & culture | C24: =INDEX($F$8:$F$15,MATCH(A24,$N$8:$N$15,0)) -> 0.058524853 | D24: =INDEX($E$8:$E$15,MATCH(A24,$N$8:$N$15,0)) -> 0.15668203 | E24: =INDEX($G$8:$G$15,MATCH(A24,$N$8:$N$15,0)) -> 9.8157175 | F24: =INDEX($J$8:$J$15,MATCH(A24,$N$8:$N$15,0)) -> 9.0539932e-09
A25: 7 | B25: =INDEX($B$8:$B$15,MATCH(A25,$N$8:$N$15,0)) -> Defence & foreign | C25: =INDEX($F$8:$F$15,MATCH(A25,$N$8:$N$15,0)) -> 0.040352753 | D25: =INDEX($E$8:$E$15,MATCH(A25,$N$8:$N$15,0)) -> 0.064516129 | E25: =INDEX($G$8:$G$15,MATCH(A25,$N$8:$N$15,0)) -> 2.4163376 | F25: =INDEX($J$8:$J$15,MATCH(A25,$N$8:$N$15,0)) -> 0.083349127
A26: 8 | B26: =INDEX($B$8:$B$15,MATCH(A26,$N$8:$N$15,0)) -> Islam | C26: =INDEX($F$8:$F$15,MATCH(A26,$N$8:$N$15,0)) -> 0.035275254 | D26: =INDEX($E$8:$E$15,MATCH(A26,$N$8:$N$15,0)) -> 0.13364055 | E26: =INDEX($G$8:$G$15,MATCH(A26,$N$8:$N$15,0)) -> 9.8365299 | F26: =INDEX($J$8:$J$15,MATCH(A26,$N$8:$N$15,0)) -> 9.8747793e-13
A29: Topic shares among topical posts: AI (full visuals) vs conventional
A30: Sample: all AI items plus up to 300 conventional posts per account (month-stratified; smaller accounts in full). Branding-only and AI-indeterminate posts excluded.
A32: Table A: no-topic share of all posts. Table B: topic shares of topical posts (>= 1 topic).
A36: A – Posts with no topic, share of all posts
A37: group | B37: n posts | C37: n no topic | D37: share no topic | E37: n topical | F37: share no topic, standardised to AI account mix
A38: AI (full visuals) | B38: =SUMPRODUCT(Posts!$V$3:$V$6208) -> 217 | C38: =SUMPRODUCT(Posts!$V$3:$V$6208,1-Posts!$U$3:$U$6208) -> 27 | D38: =C38/B38 -> 0.12442396 | E38: =SUMPRODUCT(Posts!$V$3:$V$6208,Posts!$U$3:$U$6208) -> 190
A39: Conventional | B39: =SUMPRODUCT(Posts!$S$3:$S$6208) -> 3742 | C39: =SUMPRODUCT(Posts!$S$3:$S$6208,1-Posts!$U$3:$U$6208) -> 1281 | D39: =C39/B39 -> 0.3423303 | E39: =SUMPRODUCT(Posts!$S$3:$S$6208,Posts!$U$3:$U$6208) -> 2461 | F39: =SUMPRODUCT(COUNTIFS(acct,acc_tbl,is_conv,1,topical,0)/COUNTIFS(acct,acc_tbl,is_conv,1),COUNTIFS(acct,acc_tbl,ai_full,1))/$B$38 -> 0.2923288
A41: χ² | B41: =(B38+B39)*(C38*(B39-C39)-(B38-C38)*C39)^2/(B38*B39*(C38+C39)*(B38+B39-C38-C39)) -> 44.022154
A42: p | B42: =_xlfn.CHISQ.DIST.RT(B41,1) -> 3.2468019e-11
A45: B – Topic shares among topical posts (>= 1 topic)
A46: code | B46: label | C46: n AI | D46: n conv | E46: share AI | F46: share conv | G46: diff (pp) | H46: ratio AI/conv | I46: χ² | J46: p | L46: share conv, standardised to AI account mix | M46: diff standardised (pp)
A47: IMM | B47: Immigration | C47: =SUMPRODUCT(Posts!$V$3:$V$6208,Posts!$U$3:$U$6208,Posts!$I$3:$I$6208) -> 79 | D47: =SUMPRODUCT(Posts!$S$3:$S$6208,Posts!$U$3:$U$6208,Posts!$I$3:$I$6208) -> 832 | E47: =C47/$E$38 -> 0.41578947 | F47: =D47/$E$39 -> 0.33807395 | G47: =(E47-F47)*100 -> 7.771552 | H47: =E47/F47 -> 1.2298773 | I47: =($E$38+$E$39)*(C47*($E$39-D47)-($E$38-C47)*D47)^2/($E$38*$E$39*(C47+D47)*($E$38+$E$39-C47-D47)) -> 4.7230531 | J47: =_xlfn.CHISQ.DIST.RT(I47,1) -> 0.029760856 | L47: =SUMPRODUCT(COUNTIFS(acct,acc_tbl,is_conv,1,topical,1,T_IMM,1)/COUNTIFS(acct,acc_tbl,is_conv,1,topical,1),COUNTIFS(acct,acc_tbl,ai_full,1,topical,1))/$E$38 -> 0.34084381 | M47: =(E47-L47)*100 -> 7.4945663
A48: ISL | B48: Islam | C48: =SUMPRODUCT(Posts!$V$3:$V$6208,Posts!$U$3:$U$6208,Posts!$J$3:$J$6208) -> 29 | D48: =SUMPRODUCT(Posts!$S$3:$S$6208,Posts!$U$3:$U$6208,Posts!$J$3:$J$6208) -> 132 | E48: =C48/$E$38 -> 0.15263158 | F48: =D48/$E$39 -> 0.053636733 | G48: =(E48-F48)*100 -> 9.8994846 | H48: =E48/F48 -> 2.8456539 | I48: =($E$38+$E$39)*(C48*($E$39-D48)-($E$38-C48)*D48)^2/($E$38*$E$39*(C48+D48)*($E$38+$E$39-C48-D48)) -> 30.302251 | J48: =_xlfn.CHISQ.DIST.RT(I48,1) -> 3.6969667e-08 | L48: =SUMPRODUCT(COUNTIFS(acct,acc_tbl,is_conv,1,topical,1,T_ISL,1)/COUNTIFS(acct,acc_tbl,is_conv,1,topical,1),COUNTIFS(acct,acc_tbl,ai_full,1,topical,1))/$E$38 -> 0.0596061 | M48: =(E48-L48)*100 -> 9.3025479
A49: CRI | B49: Crime & security | C49: =SUMPRODUCT(Posts!$V$3:$V$6208,Posts!$U$3:$U$6208,Posts!$K$3:$K$6208) -> 50 | D49: =SUMPRODUCT(Posts!$S$3:$S$6208,Posts!$U$3:$U$6208,Posts!$K$3:$K$6208) -> 606 | E49: =C49/$E$38 -> 0.26315789 | F49: =D49/$E$39 -> 0.24624137 | G49: =(E49-F49)*100 -> 1.6916529 | H49: =E49/F49 -> 1.068699 | I49: =($E$38+$E$39)*(C49*($E$39-D49)-($E$38-C49)*D49)^2/($E$38*$E$39*(C49+D49)*($E$38+$E$39-C49-D49)) -> 0.27105083 | J49: =_xlfn.CHISQ.DIST.RT(I49,1) -> 0.60262774 | L49: =SUMPRODUCT(COUNTIFS(acct,acc_tbl,is_conv,1,topical,1,T_CRI,1)/COUNTIFS(acct,acc_tbl,is_conv,1,topical,1),COUNTIFS(acct,acc_tbl,ai_full,1,topical,1))/$E$38 -> 0.27871446 | M49: =(E49-L49)*100 -> -1.5556561
A50: SOV | B50: Sovereignty & identity | C50: =SUMPRODUCT(Posts!$V$3:$V$6208,Posts!$U$3:$U$6208,Posts!$L$3:$L$6208) -> 55 | D50: =SUMPRODUCT(Posts!$S$3:$S$6208,Posts!$U$3:$U$6208,Posts!$L$3:$L$6208) -> 987 | E50: =C50/$E$38 -> 0.28947368 | F50: =D50/$E$39 -> 0.40105648 | G50: =(E50-F50)*100 -> -11.15828 | H50: =E50/F50 -> 0.72177785 | I50: =($E$38+$E$39)*(C50*($E$39-D50)-($E$38-C50)*D50)^2/($E$38*$E$39*(C50+D50)*($E$38+$E$39-C50-D50)) -> 9.2054636 | J50: =_xlfn.CHISQ.DIST.RT(I50,1) -> 0.0024129388 | L50: =SUMPRODUCT(COUNTIFS(acct,acc_tbl,is_conv,1,topical,1,T_SOV,1)/COUNTIFS(acct,acc_tbl,is_conv,1,topical,1),COUNTIFS(acct,acc_tbl,ai_full,1,topical,1))/$E$38 -> 0.33380648 | M50: =(E50-L50)*100 -> -4.4332794
A51: ECON | B51: Economy & services | C51: =SUMPRODUCT(Posts!$V$3:$V$6208,Posts!$U$3:$U$6208,Posts!$M$3:$M$6208) -> 68 | D51: =SUMPRODUCT(Posts!$S$3:$S$6208,Posts!$U$3:$U$6208,Posts!$M$3:$M$6208) -> 943 | E51: =C51/$E$38 -> 0.35789474 | F51: =D51/$E$39 -> 0.38317757 | G51: =(E51-F51)*100 -> -2.5282833 | H51: =E51/F51 -> 0.93401797 | I51: =($E$38+$E$39)*(C51*($E$39-D51)-($E$38-C51)*D51)^2/($E$38*$E$39*(C51+D51)*($E$38+$E$39-C51-D51)) -> 0.47789383 | J51: =_xlfn.CHISQ.DIST.RT(I51,1) -> 0.48937788 | L51: =SUMPRODUCT(COUNTIFS(acct,acc_tbl,is_conv,1,topical,1,T_ECON,1)/COUNTIFS(acct,acc_tbl,is_conv,1,topical,1),COUNTIFS(acct,acc_tbl,ai_full,1,topical,1))/$E$38 -> 0.3573844 | M51: =(E51-L51)*100 -> 0.051033806
A52: LAND | B52: Land & environment | C52: =SUMPRODUCT(Posts!$V$3:$V$6208,Posts!$U$3:$U$6208,Posts!$N$3:$N$6208) -> 33 | D52: =SUMPRODUCT(Posts!$S$3:$S$6208,Posts!$U$3:$U$6208,Posts!$N$3:$N$6208) -> 441 | E52: =C52/$E$38 -> 0.17368421 | F52: =D52/$E$39 -> 0.17919545 | G52: =(E52-F52)*100 -> -0.55112385 | H52: =E52/F52 -> 0.96924454 | I52: =($E$38+$E$39)*(C52*($E$39-D52)-($E$38-C52)*D52)^2/($E$38*$E$39*(C52+D52)*($E$38+$E$39-C52-D52)) -> 0.036486867 | J52: =_xlfn.CHISQ.DIST.RT(I52,1) -> 0.84851356 | L52: =SUMPRODUCT(COUNTIFS(acct,acc_tbl,is_conv,1,topical,1,T_LAND,1)/COUNTIFS(acct,acc_tbl,is_conv,1,topical,1),COUNTIFS(acct,acc_tbl,ai_full,1,topical,1))/$E$38 -> 0.22572178 | M52: =(E52-L52)*100 -> -5.2037567
...

Sheet Register
A1: Every Chapter 4.4 number as a formula cell
A2: All tables are formulas over Register_AI / Register_Conv.
A3: Scene items = branding_only 0 (AI 217, conventional 444). Negative = any slot menace/othering/ridicule/blame/victim; positive = any slot wholesome/heroic and not negative; neutral = neither.
A5: Chi-square: Pearson 1 df, no continuity correction; indicative where an expected cell < 5.
A10: Denominators (scene items)
A11: n AI scene items | B11: =SUM(Register_AI!$P$2:$P$288) -> 217
A12: n conventional scene items | B12: =SUM(Register_Conv!$P$2:$P$487) -> 444
A14: S2. Subject
A15: S2 – Subject shown, slot 1, share of scene items (secondary table; the F2 chart now reads the any-slot table from row 108)
A16: label | B16: n AI | C16: n conv | D16: share AI | E16: share conv | F16: diff (pp) | G16: χ² | H16: p
A17: Own leader | B17: =SUMPRODUCT((Register_AI!$G$2:$G$288="own_leader")*Register_AI!$P$2:$P$288) -> 14 | C17: =SUMPRODUCT((Register_Conv!$G$2:$G$487="own_leader")*Register_Conv!$P$2:$P$487) -> 223 | D17: =B17/$B$11 -> 0.064516129 | E17: =C17/$B$12 -> 0.50225225 | F17: =(D17-E17)*100 -> -43.773612 | G17: =IFERROR((B17+($B$11-B17)+C17+($B$12-C17))*(B17*($B$12-C17)-($B$11-B17)*C17)^2/((B17+($B$11-B17))*(C17+($B$12-C17))*(B17+C17)*(($B$11-B17)+($B$12-C17))),"") -> 121.43804 | H17: =IFERROR(_xlfn.CHISQ.DIST.RT(G17,1),"") -> 3.0642396e-28
A18: Party politician | B18: =SUMPRODUCT((Register_AI!$G$2:$G$288="party_politician")*Register_AI!$P$2:$P$288) -> 0 | C18: =SUMPRODUCT((Register_Conv!$G$2:$G$487="party_politician")*Register_Conv!$P$2:$P$487) -> 47 | D18: =B18/$B$11 -> 0 | E18: =C18/$B$12 -> 0.10585586 | F18: =(D18-E18)*100 -> -10.585586 | G18: =IFERROR((B18+($B$11-B18)+C18+($B$12-C18))*(B18*($B$12-C18)-($B$11-B18)*C18)^2/((B18+($B$11-B18))*(C18+($B$12-C18))*(B18+C18)*(($B$11-B18)+($B$12-C18))),"") -> 24.729066 | H18: =IFERROR(_xlfn.CHISQ.DIST.RT(G18,1),"") -> 6.5981575e-07
A19: Other politician | B19: =SUMPRODUCT((Register_AI!$G$2:$G$288="politician")*Register_AI!$P$2:$P$288) -> 25 | C19: =SUMPRODUCT((Register_Conv!$G$2:$G$487="politician")*Register_Conv!$P$2:$P$487) -> 59 | D19: =B19/$B$11 -> 0.11520737 | E19: =C19/$B$12 -> 0.13288288 | F19: =(D19-E19)*100 -> -1.767551 | G19: =IFERROR((B19+($B$11-B19)+C19+($B$12-C19))*(B19*($B$12-C19)-($B$11-B19)*C19)^2/((B19+($B$11-B19))*(C19+($B$12-C19))*(B19+C19)*(($B$11-B19)+($B$12-C19))),"") -> 0.41051871 | H19: =IFERROR(_xlfn.CHISQ.DIST.RT(G19,1),"") -> 0.52170635
A20: Anonymous individual | B20: =SUMPRODUCT((Register_AI!$G$2:$G$288="individual")*Register_AI!$P$2:$P$288) -> 107 | C20: =SUMPRODUCT((Register_Conv!$G$2:$G$487="individual")*Register_Conv!$P$2:$P$487) -> 39 | D20: =B20/$B$11 -> 0.49308756 | E20: =C20/$B$12 -> 0.087837838 | F20: =(D20-E20)*100 -> 40.524972 | G20: =IFERROR((B20+($B$11-B20)+C20+($B$12-C20))*(B20*($B$12-C20)-($B$11-B20)*C20)^2/((B20+($B$11-B20))*(C20+($B$12-C20))*(B20+C20)*(($B$11-B20)+($B$12-C20))),"") -> 139.10077 | H20: =IFERROR(_xlfn.CHISQ.DIST.RT(G20,1),"") -> 4.1865817e-32
A21: Mass | B21: =SUMPRODUCT((Register_AI!$G$2:$G$288="mass")*Register_AI!$P$2:$P$288) -> 25 | C21: =SUMPRODUCT((Register_Conv!$G$2:$G$487="mass")*Register_Conv!$P$2:$P$487) -> 25 | D21: =B21/$B$11 -> 0.11520737 | E21: =C21/$B$12 -> 0.056306306 | F21: =(D21-E21)*100 -> 5.8901067 | G21: =IFERROR((B21+($B$11-B21)+C21+($B$12-C21))*(B21*($B$12-C21)-($B$11-B21)*C21)^2/((B21+($B$11-B21))*(C21+($B$12-C21))*(B21+C21)*(($B$11-B21)+($B$12-C21))),"") -> 7.2323473 | H21: =IFERROR(_xlfn.CHISQ.DIST.RT(G21,1),"") -> 0.0071601528
A22: Institution | B22: =SUMPRODUCT((Register_AI!$G$2:$G$288="institution")*Register_AI!$P$2:$P$288) -> 12 | C22: =SUMPRODUCT((Register_Conv!$G$2:$G$487="institution")*Register_Conv!$P$2:$P$487) -> 7 | D22: =B22/$B$11 -> 0.055299539 | E22: =C22/$B$12 -> 0.015765766 | F22: =(D22-E22)*100 -> 3.9533773 | G22: =IFERROR((B22+($B$11-B22)+C22+($B$12-C22))*(B22*($B$12-C22)-($B$11-B22)*C22)^2/((B22+($B$11-B22))*(C22+($B$12-C22))*(B22+C22)*(($B$11-B22)+($B$12-C22))),"") -> 8.1600359 | H22: =IFERROR(_xlfn.CHISQ.DIST.RT(G22,1),"") -> 0.0042823523
A23: Economy | B23: =SUMPRODUCT((Register_AI!$G$2:$G$288="economy")*Register_AI!$P$2:$P$288) -> 9 | C23: =SUMPRODUCT((Register_Conv!$G$2:$G$487="economy")*Register_Conv!$P$2:$P$487) -> 4 | D23: =B23/$B$11 -> 0.041474654 | E23: =C23/$B$12 -> 0.009009009 | F23: =(D23-E23)*100 -> 3.2465645 | G23: =IFERROR((B23+($B$11-B23)+C23+($B$12-C23))*(B23*($B$12-C23)-($B$11-B23)*C23)^2/((B23+($B$11-B23))*(C23+($B$12-C23))*(B23+C23)*(($B$11-B23)+($B$12-C23))),"") -> 7.9684506 | H23: =IFERROR(_xlfn.CHISQ.DIST.RT(G23,1),"") -> 0.0047599664
A24: Place | B24: =SUMPRODUCT((Register_AI!$G$2:$G$288="place")*Register_AI!$P$2:$P$288) -> 6 | C24: =SUMPRODUCT((Register_Conv!$G$2:$G$487="place")*Register_Conv!$P$2:$P$487) -> 7 | D24: =B24/$B$11 -> 0.02764977 | E24: =C24/$B$12 -> 0.015765766 | F24: =(D24-E24)*100 -> 1.1884004 | G24: =IFERROR((B24+($B$11-B24)+C24+($B$12-C24))*(B24*($B$12-C24)-($B$11-B24)*C24)^2/((B24+($B$11-B24))*(C24+($B$12-C24))*(B24+C24)*(($B$11-B24)+($B$12-C24))),"") -> 1.0677052 | H24: =IFERROR(_xlfn.CHISQ.DIST.RT(G24,1),"") -> 0.30146436
A25: Object | B25: =SUMPRODUCT((Register_AI!$G$2:$G$288="object")*Register_AI!$P$2:$P$288) -> 17 | C25: =SUMPRODUCT((Register_Conv!$G$2:$G$487="object")*Register_Conv!$P$2:$P$487) -> 21 | D25: =B25/$B$11 -> 0.078341014 | E25: =C25/$B$12 -> 0.047297297 | F25: =(D25-E25)*100 -> 3.1043717 | G25: =IFERROR((B25+($B$11-B25)+C25+($B$12-C25))*(B25*($B$12-C25)-($B$11-B25)*C25)^2/((B25+($B$11-B25))*(C25+($B$12-C25))*(B25+C25)*(($B$11-B25)+($B$12-C25))),"") -> 2.592507 | H25: =IFERROR(_xlfn.CHISQ.DIST.RT(G25,1),"") -> 0.10737027
A26: No subject | B26: =SUMPRODUCT((Register_AI!$G$2:$G$288="none")*Register_AI!$P$2:$P$288) -> 2 | C26: =SUMPRODUCT((Register_Conv!$G$2:$G$487="none")*Register_Conv!$P$2:$P$487) -> 12 | D26: =B26/$B$11 -> 0.0092165899 | E26: =C26/$B$12 -> 0.027027027 | F26: =(D26-E26)*100 -> -1.7810437 | G26: =IFERROR((B26+($B$11-B26)+C26+($B$12-C26))*(B26*($B$12-C26)-($B$11-B26)*C26)^2/((B26+($B$11-B26))*(C26+($B$12-C26))*(B26+C26)*(($B$11-B26)+($B$12-C26))),"") -> 2.2302883 | H26: =IFERROR(_xlfn.CHISQ.DIST.RT(G26,1),"") -> 0.13532859
A27: Own leader in any slot (count / share)
A28: AI | B28: =SUM(Register_AI!$T$2:$T$288) -> 37 | D28: =B28/$B$11 -> 0.17050691
A29: Conventional | B29: =SUM(Register_Conv!$T$2:$T$487) -> 240 | D29: =B29/$B$12 -> 0.54054054
A31: Party politician in any slot (count / share)
A32: AI | B32: =SUMPRODUCT(Register_AI!$P$2:$P$288*(((Register_AI!$G$2:$G$288="party_politician")+(Register_AI!$I$2:$I$288="party_politician")+(Register_AI!$K$2:$K$288="party_politician"))>0)) -> 11 | D32: =B32/$B$11 -> 0.050691244
A33: Conventional | B33: =SUMPRODUCT(Register_Conv!$P$2:$P$487*(((Register_Conv!$G$2:$G$487="party_politician")+(Register_Conv!$I$2:$I$487="party_politician")+(Register_Conv!$K$2:$K$487="party_politician"))>0)) -> 77 | D33: =B33/$B$12 -> 0.17342342
A35: How the subject is treated (predication, slot 1), share of scene items (secondary table; the F3 chart now reads the any-slot table from row 129)
B37: AI-generated n | C37: Conventional n | D37: AI-generated | E37: Conventional
A38: None | B38: =COUNTIFS(Register_AI!$F$2:$F$288,0,Register_AI!$H$2:$H$288,"none") -> 51 | C38: =COUNTIFS(Register_Conv!$F$2:$F$487,0,Register_Conv!$H$2:$H$487,"none") -> 306 | D38: =B38/B$46 -> 0.23502304 | E38: =C38/C$46 -> 0.68918919
A39: Menace | B39: =COUNTIFS(Register_AI!$F$2:$F$288,0,Register_AI!$H$2:$H$288,"menace") -> 39 | C39: =COUNTIFS(Register_Conv!$F$2:$F$487,0,Register_Conv!$H$2:$H$487,"menace") -> 19 | D39: =B39/B$46 -> 0.1797235 | E39: =C39/C$46 -> 0.042792793
A40: Othering | B40: =COUNTIFS(Register_AI!$F$2:$F$288,0,Register_AI!$H$2:$H$288,"othering") -> 15 | C40: =COUNTIFS(Register_Conv!$F$2:$F$487,0,Register_Conv!$H$2:$H$487,"othering") -> 5 | D40: =B40/B$46 -> 0.069124424 | E40: =C40/C$46 -> 0.011261261
A41: Ridicule | B41: =COUNTIFS(Register_AI!$F$2:$F$288,0,Register_AI!$H$2:$H$288,"ridicule") -> 16 | C41: =COUNTIFS(Register_Conv!$F$2:$F$487,0,Register_Conv!$H$2:$H$487,"ridicule") -> 3 | D41: =B41/B$46 -> 0.073732719 | E41: =C41/C$46 -> 0.0067567568
A42: Blame | B42: =COUNTIFS(Register_AI!$F$2:$F$288,0,Register_AI!$H$2:$H$288,"blame") -> 4 | C42: =COUNTIFS(Register_Conv!$F$2:$F$487,0,Register_Conv!$H$2:$H$487,"blame") -> 5 | D42: =B42/B$46 -> 0.01843318 | E42: =C42/C$46 -> 0.011261261
A43: Victim | B43: =COUNTIFS(Register_AI!$F$2:$F$288,0,Register_AI!$H$2:$H$288,"victim") -> 26 | C43: =COUNTIFS(Register_Conv!$F$2:$F$487,0,Register_Conv!$H$2:$H$487,"victim") -> 15 | D43: =B43/B$46 -> 0.11981567 | E43: =C43/C$46 -> 0.033783784
A44: Heroic | B44: =COUNTIFS(Register_AI!$F$2:$F$288,0,Register_AI!$H$2:$H$288,"heroic") -> 9 | C44: =COUNTIFS(Register_Conv!$F$2:$F$487,0,Register_Conv!$H$2:$H$487,"heroic") -> 41 | D44: =B44/B$46 -> 0.041474654 | E44: =C44/C$46 -> 0.092342342
A45: Wholesome | B45: =COUNTIFS(Register_AI!$F$2:$F$288,0,Register_AI!$H$2:$H$288,"wholesome") -> 57 | C45: =COUNTIFS(Register_Conv!$F$2:$F$487,0,Register_Conv!$H$2:$H$487,"wholesome") -> 50 | D45: =B45/B$46 -> 0.26267281 | E45: =C45/C$46 -> 0.11261261
A46: Base (n) | B46: =COUNTIFS(Register_AI!$F$2:$F$288,0) -> 217 | C46: =COUNTIFS(Register_Conv!$F$2:$F$487,0) -> 444
A57: S3. Imagery treatment
A58: S3b – Imagery treatment, any slot
A59: label | B59: n AI | C59: n conv | D59: share AI | E59: share conv | F59: diff (pp) | G59: χ² | H59: p
...

Sheet Register_AI
A1: seq | B1: i | C1: account | D1: country | E1: date | F1: branding_only | G1: subject1 | H1: predication1 | I1: subject2 | J1: predication2 | K1: subject3 | L1: predication3 | M1: subject1_AI | N1: subject2_AI | O1: subject3_AI | P1: scene | Q1: neg_pic | R1: pos_pic | S1: neu_pic | T1: own_leader_any
A2: 1 | B2: 696 | C2: BE_EU_vlaamsbelang | D2: BE | E2: 45335 | F2: 0 | G2: object | H2: victim | I2: institution | J2: blame | M2: TRUE | N2: TRUE | P2: =IF(F2=0,1,0) -> 1 | Q2: =IF(AND(P2=1,OR(ISNUMBER(MATCH(H2,{"menace","othering","ridicule","blame","victim"},0)),ISNUMBER(MATCH(J2,{"menace","othering","ridicule","blame","victim"},0)),ISNUMBER(MATCH(L2,{"menace","othering","ridicule","blame","victim"},0)))),1,0) -> 1 | R2: =IF(AND(P2=1,Q2=0,OR(ISNUMBER(MATCH(H2,{"wholesome","heroic"},0)),ISNUMBER(MATCH(J2,{"wholesome","heroic"},0)),ISNUMBER(MATCH(L2,{"wholesome","heroic"},0)))),1,0) -> 0 | S2: =IF(AND(P2=1,Q2=0,R2=0),1,0) -> 0 | T2: =IF(AND(P2=1,OR(G2="own_leader",I2="own_leader",K2="own_leader")),1,0) -> 0
A3: 2 | B3: 703 | C3: BE_EU_vlaamsbelang | D3: BE | E3: 45344 | F3: 0 | G3: institution | H3: heroic | M3: TRUE | P3: =IF(F3=0,1,0) -> 1 | Q3: =IF(AND(P3=1,OR(ISNUMBER(MATCH(H3,{"menace","othering","ridicule","blame","victim"},0)),ISNUMBER(MATCH(J3,{"menace","othering","ridicule","blame","victim"},0)),ISNUMBER(MATCH(L3,{"menace","othering","ridicule","blame","victim"},0)))),1,0) -> 0 | R3: =IF(AND(P3=1,Q3=0,OR(ISNUMBER(MATCH(H3,{"wholesome","heroic"},0)),ISNUMBER(MATCH(J3,{"wholesome","heroic"},0)),ISNUMBER(MATCH(L3,{"wholesome","heroic"},0)))),1,0) -> 1 | S3: =IF(AND(P3=1,Q3=0,R3=0),1,0) -> 0 | T3: =IF(AND(P3=1,OR(G3="own_leader",I3="own_leader",K3="own_leader")),1,0) -> 0
A4: 3 | B4: 742 | C4: BE_EU_vlaamsbelang | D4: BE | E4: 45384 | F4: 0 | G4: mass | H4: menace | M4: TRUE | P4: =IF(F4=0,1,0) -> 1 | Q4: =IF(AND(P4=1,OR(ISNUMBER(MATCH(H4,{"menace","othering","ridicule","blame","victim"},0)),ISNUMBER(MATCH(J4,{"menace","othering","ridicule","blame","victim"},0)),ISNUMBER(MATCH(L4,{"menace","othering","ridicule","blame","victim"},0)))),1,0) -> 1 | R4: =IF(AND(P4=1,Q4=0,OR(ISNUMBER(MATCH(H4,{"wholesome","heroic"},0)),ISNUMBER(MATCH(J4,{"wholesome","heroic"},0)),ISNUMBER(MATCH(L4,{"wholesome","heroic"},0)))),1,0) -> 0 | S4: =IF(AND(P4=1,Q4=0,R4=0),1,0) -> 0 | T4: =IF(AND(P4=1,OR(G4="own_leader",I4="own_leader",K4="own_leader")),1,0) -> 0
A5: 4 | B5: 872 | C5: DE_afd.bund | D5: DE | E5: 45594 | F5: 0 | G5: economy | H5: victim | M5: TRUE | P5: =IF(F5=0,1,0) -> 1 | Q5: =IF(AND(P5=1,OR(ISNUMBER(MATCH(H5,{"menace","othering","ridicule","blame","victim"},0)),ISNUMBER(MATCH(J5,{"menace","othering","ridicule","blame","victim"},0)),ISNUMBER(MATCH(L5,{"menace","othering","ridicule","blame","victim"},0)))),1,0) -> 1 | R5: =IF(AND(P5=1,Q5=0,OR(ISNUMBER(MATCH(H5,{"wholesome","heroic"},0)),ISNUMBER(MATCH(J5,{"wholesome","heroic"},0)),ISNUMBER(MATCH(L5,{"wholesome","heroic"},0)))),1,0) -> 0 | S5: =IF(AND(P5=1,Q5=0,R5=0),1,0) -> 0 | T5: =IF(AND(P5=1,OR(G5="own_leader",I5="own_leader",K5="own_leader")),1,0) -> 0
A6: 5 | B6: 873 | C6: DE_afd.bund | D6: DE | E6: 45595 | F6: 0 | G6: politician | H6: ridicule | M6: FALSE | P6: =IF(F6=0,1,0) -> 1 | Q6: =IF(AND(P6=1,OR(ISNUMBER(MATCH(H6,{"menace","othering","ridicule","blame","victim"},0)),ISNUMBER(MATCH(J6,{"menace","othering","ridicule","blame","victim"},0)),ISNUMBER(MATCH(L6,{"menace","othering","ridicule","blame","victim"},0)))),1,0) -> 1 | R6: =IF(AND(P6=1,Q6=0,OR(ISNUMBER(MATCH(H6,{"wholesome","heroic"},0)),ISNUMBER(MATCH(J6,{"wholesome","heroic"},0)),ISNUMBER(MATCH(L6,{"wholesome","heroic"},0)))),1,0) -> 0 | S6: =IF(AND(P6=1,Q6=0,R6=0),1,0) -> 0 | T6: =IF(AND(P6=1,OR(G6="own_leader",I6="own_leader",K6="own_leader")),1,0) -> 0
A7: 6 | B7: 874 | C7: DE_afd.bund | D7: DE | E7: 45595 | F7: 0 | G7: object | H7: none | M7: TRUE | P7: =IF(F7=0,1,0) -> 1 | Q7: =IF(AND(P7=1,OR(ISNUMBER(MATCH(H7,{"menace","othering","ridicule","blame","victim"},0)),ISNUMBER(MATCH(J7,{"menace","othering","ridicule","blame","victim"},0)),ISNUMBER(MATCH(L7,{"menace","othering","ridicule","blame","victim"},0)))),1,0) -> 0 | R7: =IF(AND(P7=1,Q7=0,OR(ISNUMBER(MATCH(H7,{"wholesome","heroic"},0)),ISNUMBER(MATCH(J7,{"wholesome","heroic"},0)),ISNUMBER(MATCH(L7,{"wholesome","heroic"},0)))),1,0) -> 0 | S7: =IF(AND(P7=1,Q7=0,R7=0),1,0) -> 1 | T7: =IF(AND(P7=1,OR(G7="own_leader",I7="own_leader",K7="own_leader")),1,0) -> 0
A8: 7 | B8: 875 | C8: DE_afd.bund | D8: DE | E8: 45596 | F8: 0 | G8: individual | H8: wholesome | M8: TRUE | P8: =IF(F8=0,1,0) -> 1 | Q8: =IF(AND(P8=1,OR(ISNUMBER(MATCH(H8,{"menace","othering","ridicule","blame","victim"},0)),ISNUMBER(MATCH(J8,{"menace","othering","ridicule","blame","victim"},0)),ISNUMBER(MATCH(L8,{"menace","othering","ridicule","blame","victim"},0)))),1,0) -> 0 | R8: =IF(AND(P8=1,Q8=0,OR(ISNUMBER(MATCH(H8,{"wholesome","heroic"},0)),ISNUMBER(MATCH(J8,{"wholesome","heroic"},0)),ISNUMBER(MATCH(L8,{"wholesome","heroic"},0)))),1,0) -> 1 | S8: =IF(AND(P8=1,Q8=0,R8=0),1,0) -> 0 | T8: =IF(AND(P8=1,OR(G8="own_leader",I8="own_leader",K8="own_leader")),1,0) -> 0
A9: 8 | B9: 876 | C9: DE_afd.bund | D9: DE | E9: 45596 | F9: 0 | G9: individual | H9: menace | M9: TRUE | P9: =IF(F9=0,1,0) -> 1 | Q9: =IF(AND(P9=1,OR(ISNUMBER(MATCH(H9,{"menace","othering","ridicule","blame","victim"},0)),ISNUMBER(MATCH(J9,{"menace","othering","ridicule","blame","victim"},0)),ISNUMBER(MATCH(L9,{"menace","othering","ridicule","blame","victim"},0)))),1,0) -> 1 | R9: =IF(AND(P9=1,Q9=0,OR(ISNUMBER(MATCH(H9,{"wholesome","heroic"},0)),ISNUMBER(MATCH(J9,{"wholesome","heroic"},0)),ISNUMBER(MATCH(L9,{"wholesome","heroic"},0)))),1,0) -> 0 | S9: =IF(AND(P9=1,Q9=0,R9=0),1,0) -> 0 | T9: =IF(AND(P9=1,OR(G9="own_leader",I9="own_leader",K9="own_leader")),1,0) -> 0
A10: 9 | B10: 877 | C10: DE_afd.bund | D10: DE | E10: 45597 | F10: 0 | G10: individual | H10: wholesome | M10: TRUE | P10: =IF(F10=0,1,0) -> 1 | Q10: =IF(AND(P10=1,OR(ISNUMBER(MATCH(H10,{"menace","othering","ridicule","blame","victim"},0)),ISNUMBER(MATCH(J10,{"menace","othering","ridicule","blame","victim"},0)),ISNUMBER(MATCH(L10,{"menace","othering","ridicule","blame","victim"},0)))),1,0) -> 0 | R10: =IF(AND(P10=1,Q10=0,OR(ISNUMBER(MATCH(H10,{"wholesome","heroic"},0)),ISNUMBER(MATCH(J10,{"wholesome","heroic"},0)),ISNUMBER(MATCH(L10,{"wholesome","heroic"},0)))),1,0) -> 1 | S10: =IF(AND(P10=1,Q10=0,R10=0),1,0) -> 0 | T10: =IF(AND(P10=1,OR(G10="own_leader",I10="own_leader",K10="own_leader")),1,0) -> 0
A11: 10 | B11: 879 | C11: DE_afd.bund | D11: DE | E11: 45600 | F11: 0 | G11: institution | H11: ridicule | I11: politician | J11: blame | M11: TRUE | N11: FALSE | P11: =IF(F11=0,1,0) -> 1 | Q11: =IF(AND(P11=1,OR(ISNUMBER(MATCH(H11,{"menace","othering","ridicule","blame","victim"},0)),ISNUMBER(MATCH(J11,{"menace","othering","ridicule","blame","victim"},0)),ISNUMBER(MATCH(L11,{"menace","othering","ridicule","blame","victim"},0)))),1,0) -> 1 | R11: =IF(AND(P11=1,Q11=0,OR(ISNUMBER(MATCH(H11,{"wholesome","heroic"},0)),ISNUMBER(MATCH(J11,{"wholesome","heroic"},0)),ISNUMBER(MATCH(L11,{"wholesome","heroic"},0)))),1,0) -> 0 | S11: =IF(AND(P11=1,Q11=0,R11=0),1,0) -> 0 | T11: =IF(AND(P11=1,OR(G11="own_leader",I11="own_leader",K11="own_leader")),1,0) -> 0
A12: 11 | B12: 888 | C12: DE_afd.bund | D12: DE | E12: 45607 | F12: 0 | G12: politician | H12: ridicule | M12: FALSE | P12: =IF(F12=0,1,0) -> 1 | Q12: =IF(AND(P12=1,OR(ISNUMBER(MATCH(H12,{"menace","othering","ridicule","blame","victim"},0)),ISNUMBER(MATCH(J12,{"menace","othering","ridicule","blame","victim"},0)),ISNUMBER(MATCH(L12,{"menace","othering","ridicule","blame","victim"},0)))),1,0) -> 1 | R12: =IF(AND(P12=1,Q12=0,OR(ISNUMBER(MATCH(H12,{"wholesome","heroic"},0)),ISNUMBER(MATCH(J12,{"wholesome","heroic"},0)),ISNUMBER(MATCH(L12,{"wholesome","heroic"},0)))),1,0) -> 0 | S12: =IF(AND(P12=1,Q12=0,R12=0),1,0) -> 0 | T12: =IF(AND(P12=1,OR(G12="own_leader",I12="own_leader",K12="own_leader")),1,0) -> 0
A13: 12 | B13: 892 | C13: DE_afd.bund | D13: DE | E13: 45614 | F13: 0 | G13: mass | H13: menace | I13: object | J13: none | M13: TRUE | N13: TRUE | P13: =IF(F13=0,1,0) -> 1 | Q13: =IF(AND(P13=1,OR(ISNUMBER(MATCH(H13,{"menace","othering","ridicule","blame","victim"},0)),ISNUMBER(MATCH(J13,{"menace","othering","ridicule","blame","victim"},0)),ISNUMBER(MATCH(L13,{"menace","othering","ridicule","blame","victim"},0)))),1,0) -> 1 | R13: =IF(AND(P13=1,Q13=0,OR(ISNUMBER(MATCH(H13,{"wholesome","heroic"},0)),ISNUMBER(MATCH(J13,{"wholesome","heroic"},0)),ISNUMBER(MATCH(L13,{"wholesome","heroic"},0)))),1,0) -> 0 | S13: =IF(AND(P13=1,Q13=0,R13=0),1,0) -> 0 | T13: =IF(AND(P13=1,OR(G13="own_leader",I13="own_leader",K13="own_leader")),1,0) -> 0
A14: 13 | B14: 899 | C14: DE_afd.bund | D14: DE | E14: 45618 | F14: 0 | G14: individual | H14: victim | I14: institution | J14: menace | M14: TRUE | N14: TRUE | P14: =IF(F14=0,1,0) -> 1 | Q14: =IF(AND(P14=1,OR(ISNUMBER(MATCH(H14,{"menace","othering","ridicule","blame","victim"},0)),ISNUMBER(MATCH(J14,{"menace","othering","ridicule","blame","victim"},0)),ISNUMBER(MATCH(L14,{"menace","othering","ridicule","blame","victim"},0)))),1,0) -> 1 | R14: =IF(AND(P14=1,Q14=0,OR(ISNUMBER(MATCH(H14,{"wholesome","heroic"},0)),ISNUMBER(MATCH(J14,{"wholesome","heroic"},0)),ISNUMBER(MATCH(L14,{"wholesome","heroic"},0)))),1,0) -> 0 | S14: =IF(AND(P14=1,Q14=0,R14=0),1,0) -> 0 | T14: =IF(AND(P14=1,OR(G14="own_leader",I14="own_leader",K14="own_leader")),1,0) -> 0
A15: 14 | B15: 901 | C15: DE_afd.bund | D15: DE | E15: 45622 | F15: 0 | G15: place | H15: victim | M15: TRUE | P15: =IF(F15=0,1,0) -> 1 | Q15: =IF(AND(P15=1,OR(ISNUMBER(MATCH(H15,{"menace","othering","ridicule","blame","victim"},0)),ISNUMBER(MATCH(J15,{"menace","othering","ridicule","blame","victim"},0)),ISNUMBER(MATCH(L15,{"menace","othering","ridicule","blame","victim"},0)))),1,0) -> 1 | R15: =IF(AND(P15=1,Q15=0,OR(ISNUMBER(MATCH(H15,{"wholesome","heroic"},0)),ISNUMBER(MATCH(J15,{"wholesome","heroic"},0)),ISNUMBER(MATCH(L15,{"wholesome","heroic"},0)))),1,0) -> 0 | S15: =IF(AND(P15=1,Q15=0,R15=0),1,0) -> 0 | T15: =IF(AND(P15=1,OR(G15="own_leader",I15="own_leader",K15="own_leader")),1,0) -> 0
A16: 15 | B16: 902 | C16: DE_afd.bund | D16: DE | E16: 45622 | F16: 0 | G16: individual | H16: victim | M16: TRUE | P16: =IF(F16=0,1,0) -> 1 | Q16: =IF(AND(P16=1,OR(ISNUMBER(MATCH(H16,{"menace","othering","ridicule","blame","victim"},0)),ISNUMBER(MATCH(J16,{"menace","othering","ridicule","blame","victim"},0)),ISNUMBER(MATCH(L16,{"menace","othering","ridicule","blame","victim"},0)))),1,0) -> 1 | R16: =IF(AND(P16=1,Q16=0,OR(ISNUMBER(MATCH(H16,{"wholesome","heroic"},0)),ISNUMBER(MATCH(J16,{"wholesome","heroic"},0)),ISNUMBER(MATCH(L16,{"wholesome","heroic"},0)))),1,0) -> 0 | S16: =IF(AND(P16=1,Q16=0,R16=0),1,0) -> 0 | T16: =IF(AND(P16=1,OR(G16="own_leader",I16="own_leader",K16="own_leader")),1,0) -> 0
A17: 16 | B17: 907 | C17: DE_afd.bund | D17: DE | E17: 45624 | F17: 0 | G17: individual | H17: ridicule | M17: TRUE | P17: =IF(F17=0,1,0) -> 1 | Q17: =IF(AND(P17=1,OR(ISNUMBER(MATCH(H17,{"menace","othering","ridicule","blame","victim"},0)),ISNUMBER(MATCH(J17,{"menace","othering","ridicule","blame","victim"},0)),ISNUMBER(MATCH(L17,{"menace","othering","ridicule","blame","victim"},0)))),1,0) -> 1 | R17: =IF(AND(P17=1,Q17=0,OR(ISNUMBER(MATCH(H17,{"wholesome","heroic"},0)),ISNUMBER(MATCH(J17,{"wholesome","heroic"},0)),ISNUMBER(MATCH(L17,{"wholesome","heroic"},0)))),1,0) -> 0 | S17: =IF(AND(P17=1,Q17=0,R17=0),1,0) -> 0 | T17: =IF(AND(P17=1,OR(G17="own_leader",I17="own_leader",K17="own_leader")),1,0) -> 0
A18: 17 | B18: 910 | C18: DE_afd.bund | D18: DE | E18: 45625 | F18: 0 | G18: mass | H18: menace | M18: TRUE | P18: =IF(F18=0,1,0) -> 1 | Q18: =IF(AND(P18=1,OR(ISNUMBER(MATCH(H18,{"menace","othering","ridicule","blame","victim"},0)),ISNUMBER(MATCH(J18,{"menace","othering","ridicule","blame","victim"},0)),ISNUMBER(MATCH(L18,{"menace","othering","ridicule","blame","victim"},0)))),1,0) -> 1 | R18: =IF(AND(P18=1,Q18=0,OR(ISNUMBER(MATCH(H18,{"wholesome","heroic"},0)),ISNUMBER(MATCH(J18,{"wholesome","heroic"},0)),ISNUMBER(MATCH(L18,{"wholesome","heroic"},0)))),1,0) -> 0 | S18: =IF(AND(P18=1,Q18=0,R18=0),1,0) -> 0 | T18: =IF(AND(P18=1,OR(G18="own_leader",I18="own_leader",K18="own_leader")),1,0) -> 0
A19: 18 | B19: 912 | C19: DE_afd.bund | D19: DE | E19: 45629 | F19: 0 | G19: object | H19: menace | I19: politician | J19: blame | M19: TRUE | N19: FALSE | P19: =IF(F19=0,1,0) -> 1 | Q19: =IF(AND(P19=1,OR(ISNUMBER(MATCH(H19,{"menace","othering","ridicule","blame","victim"},0)),ISNUMBER(MATCH(J19,{"menace","othering","ridicule","blame","victim"},0)),ISNUMBER(MATCH(L19,{"menace","othering","ridicule","blame","victim"},0)))),1,0) -> 1 | R19: =IF(AND(P19=1,Q19=0,OR(ISNUMBER(MATCH(H19,{"wholesome","heroic"},0)),ISNUMBER(MATCH(J19,{"wholesome","heroic"},0)),ISNUMBER(MATCH(L19,{"wholesome","heroic"},0)))),1,0) -> 0 | S19: =IF(AND(P19=1,Q19=0,R19=0),1,0) -> 0 | T19: =IF(AND(P19=1,OR(G19="own_leader",I19="own_leader",K19="own_leader")),1,0) -> 0
A20: 19 | B20: 916 | C20: DE_afd.bund | D20: DE | E20: 45631 | F20: 0 | G20: politician | H20: ridicule | M20: FALSE | P20: =IF(F20=0,1,0) -> 1 | Q20: =IF(AND(P20=1,OR(ISNUMBER(MATCH(H20,{"menace","othering","ridicule","blame","victim"},0)),ISNUMBER(MATCH(J20,{"menace","othering","ridicule","blame","victim"},0)),ISNUMBER(MATCH(L20,{"menace","othering","ridicule","blame","victim"},0)))),1,0) -> 1 | R20: =IF(AND(P20=1,Q20=0,OR(ISNUMBER(MATCH(H20,{"wholesome","heroic"},0)),ISNUMBER(MATCH(J20,{"wholesome","heroic"},0)),ISNUMBER(MATCH(L20,{"wholesome","heroic"},0)))),1,0) -> 0 | S20: =IF(AND(P20=1,Q20=0,R20=0),1,0) -> 0 | T20: =IF(AND(P20=1,OR(G20="own_leader",I20="own_leader",K20="own_leader")),1,0) -> 0
A21: 20 | B21: 917 | C21: DE_afd.bund | D21: DE | E21: 45632 | F21: 0 | G21: object | H21: none | M21: TRUE | P21: =IF(F21=0,1,0) -> 1 | Q21: =IF(AND(P21=1,OR(ISNUMBER(MATCH(H21,{"menace","othering","ridicule","blame","victim"},0)),ISNUMBER(MATCH(J21,{"menace","othering","ridicule","blame","victim"},0)),ISNUMBER(MATCH(L21,{"menace","othering","ridicule","blame","victim"},0)))),1,0) -> 0 | R21: =IF(AND(P21=1,Q21=0,OR(ISNUMBER(MATCH(H21,{"wholesome","heroic"},0)),ISNUMBER(MATCH(J21,{"wholesome","heroic"},0)),ISNUMBER(MATCH(L21,{"wholesome","heroic"},0)))),1,0) -> 0 | S21: =IF(AND(P21=1,Q21=0,R21=0),1,0) -> 1 | T21: =IF(AND(P21=1,OR(G21="own_leader",I21="own_leader",K21="own_leader")),1,0) -> 0
A22: 21 | B22: 919 | C22: DE_afd.bund | D22: DE | E22: 45632 | F22: 0 | G22: individual | H22: victim | M22: TRUE | P22: =IF(F22=0,1,0) -> 1 | Q22: =IF(AND(P22=1,OR(ISNUMBER(MATCH(H22,{"menace","othering","ridicule","blame","victim"},0)),ISNUMBER(MATCH(J22,{"menace","othering","ridicule","blame","victim"},0)),ISNUMBER(MATCH(L22,{"menace","othering","ridicule","blame","victim"},0)))),1,0) -> 1 | R22: =IF(AND(P22=1,Q22=0,OR(ISNUMBER(MATCH(H22,{"wholesome","heroic"},0)),ISNUMBER(MATCH(J22,{"wholesome","heroic"},0)),ISNUMBER(MATCH(L22,{"wholesome","heroic"},0)))),1,0) -> 0 | S22: =IF(AND(P22=1,Q22=0,R22=0),1,0) -> 0 | T22: =IF(AND(P22=1,OR(G22="own_leader",I22="own_leader",K22="own_leader")),1,0) -> 0
A23: 22 | B23: 922 | C23: DE_afd.bund | D23: DE | E23: 45635 | F23: 0 | G23: individual | H23: victim | M23: TRUE | P23: =IF(F23=0,1,0) -> 1 | Q23: =IF(AND(P23=1,OR(ISNUMBER(MATCH(H23,{"menace","othering","ridicule","blame","victim"},0)),ISNUMBER(MATCH(J23,{"menace","othering","ridicule","blame","victim"},0)),ISNUMBER(MATCH(L23,{"menace","othering","ridicule","blame","victim"},0)))),1,0) -> 1 | R23: =IF(AND(P23=1,Q23=0,OR(ISNUMBER(MATCH(H23,{"wholesome","heroic"},0)),ISNUMBER(MATCH(J23,{"wholesome","heroic"},0)),ISNUMBER(MATCH(L23,{"wholesome","heroic"},0)))),1,0) -> 0 | S23: =IF(AND(P23=1,Q23=0,R23=0),1,0) -> 0 | T23: =IF(AND(P23=1,OR(G23="own_leader",I23="own_leader",K23="own_leader")),1,0) -> 0
A24: 23 | B24: 926 | C24: DE_afd.bund | D24: DE | E24: 45639 | F24: 0 | G24: mass | H24: menace | M24: TRUE | P24: =IF(F24=0,1,0) -> 1 | Q24: =IF(AND(P24=1,OR(ISNUMBER(MATCH(H24,{"menace","othering","ridicule","blame","victim"},0)),ISNUMBER(MATCH(J24,{"menace","othering","ridicule","blame","victim"},0)),ISNUMBER(MATCH(L24,{"menace","othering","ridicule","blame","victim"},0)))),1,0) -> 1 | R24: =IF(AND(P24=1,Q24=0,OR(ISNUMBER(MATCH(H24,{"wholesome","heroic"},0)),ISNUMBER(MATCH(J24,{"wholesome","heroic"},0)),ISNUMBER(MATCH(L24,{"wholesome","heroic"},0)))),1,0) -> 0 | S24: =IF(AND(P24=1,Q24=0,R24=0),1,0) -> 0 | T24: =IF(AND(P24=1,OR(G24="own_leader",I24="own_leader",K24="own_leader")),1,0) -> 0
A25: 24 | B25: 931 | C25: DE_afd.bund | D25: DE | E25: 45643 | F25: 0 | G25: economy | H25: none | M25: TRUE | P25: =IF(F25=0,1,0) -> 1 | Q25: =IF(AND(P25=1,OR(ISNUMBER(MATCH(H25,{"menace","othering","ridicule","blame","victim"},0)),ISNUMBER(MATCH(J25,{"menace","othering","ridicule","blame","victim"},0)),ISNUMBER(MATCH(L25,{"menace","othering","ridicule","blame","victim"},0)))),1,0) -> 0 | R25: =IF(AND(P25=1,Q25=0,OR(ISNUMBER(MATCH(H25,{"wholesome","heroic"},0)),ISNUMBER(MATCH(J25,{"wholesome","heroic"},0)),ISNUMBER(MATCH(L25,{"wholesome","heroic"},0)))),1,0) -> 0 | S25: =IF(AND(P25=1,Q25=0,R25=0),1,0) -> 1 | T25: =IF(AND(P25=1,OR(G25="own_leader",I25="own_leader",K25="own_leader")),1,0) -> 0
